<?xml version="1.0" ?>
<!-- =================================================================================== -->
<!-- |    This document was autogenerated by xacro from inmoov.urdf.xacro              | -->
<!-- |    EDITING THIS FILE BY HAND IS NOT RECOMMENDED                                 | -->
<!-- =================================================================================== -->
<robot name="inmoov" xmlns:xacro="http://ros.org/wiki/xacro">
  <!-- meshlab steps taken from http://gazebosim.org/tutorials?tut=inertia -->
  <!-- assume material density is 1.0g per 1.0cm^2 -->
  <!-- ABS is 1.04g per 1.0cm^3 -->
  <!-- PLA is 1.25g per 1.0cm^3 -->
  <link name="mid_stomach_link">
    <visual>
      <geometry>
        <mesh filename="package://inmoov_description/meshes/mid_stomach.stl" scale="0.001 0.001 0.001"/>
      </geometry>
      <origin rpy="0.0 0.0 0.0" xyz="0.0 0.0 1.152"/>
      <material name="cframe">
        <color rgba="0.90 0.90 0.90 1.0"/>
      </material>
    </visual>
    <inertial>
      <mass value="1710.217625"/>
      <inertia ixx="10.129861632" ixy="0.001797694125" ixz="0.205381024" iyy="4.40146688" iyz="-0.000721074" izz="10.623296512"/>
    </inertial>
  </link>
  <link name="top_stomach_link">
    <visual>
      <geometry>
        <mesh filename="package://inmoov_description/meshes/top_stomach.stl" scale="0.001 0.001 0.001"/>
      </geometry>
      <origin rpy="0.0 0.0 0.0" xyz="0.0 0.0 0.0"/>
      <material name="cframe">
        <color rgba="0.90 0.90 0.90 1.0"/>
      </material>
    </visual>
    <inertial>
      <mass value="1144.88975"/>
      <inertia ixx="5.824147968" ixy="0.00452986" ixz="-0.222818176" iyy="4.174386432" iyz="0.00410783" izz="5.962789376"/>
    </inertial>
  </link>
  <link name="torso_link">
    <visual>
      <geometry>
        <mesh filename="package://inmoov_description/meshes/torso.stl" scale="0.001 0.001 0.001"/>
      </geometry>
      <origin rpy="0.0 0.0 0.0" xyz="0.0 0.0 0.0"/>
      <material name="cframe">
        <color rgba="0.90 0.90 0.90 1.0"/>
      </material>
    </visual>
    <inertial>
      <mass value="1923.29375"/>
      <inertia ixx="35.26709248" ixy="0.0069580865" ixz="0.730539008" iyy="25.724428288" iyz="-0.01522677" izz="13.365055488"/>
    </inertial>
  </link>
  <joint name="waist_pan_joint" type="revolute">
    <axis xyz="0.0 0.0 1.0"/>
    <limit effort="1000.0" lower="-1.0" upper="1.0" velocity="1.0"/>
    <parent link="mid_stomach_link"/>
    <child link="top_stomach_link"/>
    <origin rpy="0.0 0.0 0.0" xyz="0.0 0.0 1.152"/>
  </joint>
  <joint name="waist_roll_joint" type="revolute">
    <axis xyz="1.0 0.0 0.0"/>
    <limit effort="1000.0" lower="-0.25" upper="0.25" velocity="1.0"/>
    <parent link="top_stomach_link"/>
    <child link="torso_link"/>
    <origin rpy="0.0 0.0 0.0" xyz="0.0 0.0 0.11"/>
  </joint>
  <transmission name="waist_pan_transmission">
    <type>transmission_interface/SimpleTransmission</type>
    <joint name="waist_pan_joint">
      <hardwareInterface>hardware_interface/PositionJointInterface</hardwareInterface>
    </joint>
    <actuator name="waist_pan_motor">
      <hardwareInterface>hardware_interface/PositionJointInterface</hardwareInterface>
      <mechanicalReduction>1</mechanicalReduction>
    </actuator>
  </transmission>
  <transmission name="waist_roll_transmission">
    <type>transmission_interface/SimpleTransmission</type>
    <joint name="waist_roll_joint">
      <hardwareInterface>hardware_interface/PositionJointInterface</hardwareInterface>
    </joint>
    <actuator name="waist_roll_motor">
      <hardwareInterface>hardware_interface/PositionJointInterface</hardwareInterface>
      <mechanicalReduction>1</mechanicalReduction>
    </actuator>
  </transmission>
  <gazebo reference="mid_stomach_link">
    <material>Gazebo/Grey</material>
  </gazebo>
  <gazebo reference="top_stomach_link">
    <material>Gazebo/Grey</material>
  </gazebo>
  <gazebo reference="torso_link">
    <material>Gazebo/Grey</material>
  </gazebo>
  <link name="world"/>
  <link name="base_link">
    <visual>
      <geometry>
        <cylinder length="0.11" radius="0.26"/>
      </geometry>
      <origin rpy="0.0 0.0 0.0" xyz="0.0 0.0 0.055"/>
    </visual>
    <inertial>
      <mass value="10"/>
      <origin xyz="0.0 0.0 0.0"/>
      <inertia ixx="0.179083333333" ixy="0" ixz="0" iyy="0.179083333333" iyz="0" izz="0.338"/>
    </inertial>
  </link>
  <link name="pedestal_link">
    <visual>
      <geometry>
        <cylinder length="0.94" radius="0.0254"/>
      </geometry>
      <origin pry="0.0 0.0 0.0" xyz="0.0 0.0 0.58"/>
    </visual>
    <inertial>
      <mass value="10"/>
      <origin xyz="0.0 0.0 0.58"/>
      <inertia ixx="0.737946233333" ixy="0" ixz="0" iyy="0.737946233333" iyz="0" izz="0.0032258"/>
    </inertial>
  </link>
  <link name="r_shoulder_base_link">
    <visual>
      <geometry>
        <mesh filename="package://inmoov_description/meshes/r_shoulder_base.stl" scale="0.001 0.001 0.001"/>
      </geometry>
      <origin rpy="0.0 0.0 0.0" xyz="0.0 0.0 0.0"/>
      <material name="cframe">
        <color rgba="0.90 0.90 0.90 1.0"/>
      </material>
    </visual>
    <inertial>
      <mass value="266.52696875"/>
      <inertia ixx="0.350410112" ixy="-0.0057351625" ixz="-0.011193818" iyy="0.3908856" iyz="0.045447476" izz="0.271458688"/>
    </inertial>
  </link>
  <link name="r_shoulder_link">
    <visual>
      <geometry>
        <mesh filename="package://inmoov_description/meshes/r_shoulder.stl" scale="0.001 0.001 0.001"/>
      </geometry>
      <origin rpy="0.0 0.0 0.0" xyz="0.0 0.0 0.0"/>
      <material name="cframe">
        <color rgba="0.90 0.90 0.90 1.0"/>
      </material>
    </visual>
    <inertial>
      <mass value="322.44334375"/>
      <inertia ixx="0.60134592" ixy="0.00343772975" ixz="-0.011761917" iyy="0.473865856" iyz="-0.114277" izz="0.500951584"/>
    </inertial>
  </link>
  <link name="r_bicep_link">
    <visual>
      <geometry>
        <mesh filename="package://inmoov_description/meshes/bicep.stl" scale="0.001 0.001 0.001"/>
      </geometry>
      <origin rpy="0.0 0.0 0.0" xyz="0.0 0.0 0.0"/>
      <material name="cframe">
        <color rgba="0.90 0.90 0.90 1.0"/>
      </material>
    </visual>
    <inertial>
      <mass value="281.91265625"/>
      <inertia ixx="1.283355392" ixy="-0.000200782203125" ixz="-0.224559104" iyy="1.399255168" iyz="0.0006545236875" izz="0.416621216"/>
    </inertial>
  </link>
  <link name="r_forearm_link">
    <visual>
      <geometry>
        <mesh filename="package://inmoov_description/meshes/r_forearm.stl" scale="0.001 0.001 0.001"/>
      </geometry>
      <origin rpy="0.0 0.0 0.0" xyz="0.0 0.0 0.0"/>
      <material name="cframe">
        <color rgba="0.90 0.90 0.90 1.0"/>
      </material>
    </visual>
    <inertial>
      <mass value="401.76659375"/>
      <inertia ixx="3.242307584" ixy="0.050011216" ixz="-0.14318512" iyy="3.24251008" iyz="0.086288976" izz="0.58458784"/>
    </inertial>
  </link>
  <joint name="r_shoulder_lift_joint" type="revolute">
    <axis xyz="0.0 -1.0 0.0"/>
    <limit effort="1000.0" lower="-1.0" upper="1.0" velocity="1.0"/>
    <parent link="r_shoulder_base_link"/>
    <child link="r_shoulder_link"/>
    <origin rpy="0.0 0.0 0.0" xyz="0.0 -0.012 -0.04"/>
  </joint>
  <joint name="r_upper_arm_roll_joint" type="revolute">
    <axis xyz="0.0 0.0 1"/>
    <limit effort="1000.0" lower="-1.0" upper="1.0" velocity="1.0"/>
    <parent link="r_shoulder_link"/>
    <child link="r_bicep_link"/>
    <origin rpy="0.0 0.0 0.0" xyz="0.0 -0.066 -0.060"/>
  </joint>
  <joint name="r_elbow_flex_joint" type="revolute">
    <axis xyz="0.0 -1.0 0.0"/>
    <limit effort="1000.0" lower="0.0" upper="1.0" velocity="1.0"/>
    <parent link="r_bicep_link"/>
    <child link="r_forearm_link"/>
    <origin rpy="0.0 0.0 0.0" xyz="-0.0278 0.0 -0.2235"/>
  </joint>
  <transmission name="r_shoulder_lift_transmission">
    <type>transmission_interface/SimpleTransmission</type>
    <joint name="r_shoulder_lift_joint">
      <hardwareInterface>hardware_interface/PositionJointInterface</hardwareInterface>
    </joint>
    <actuator name="r_shoulder_lift_motor">
      <hardwareInterface>hardware_interface/PositionJointInterface</hardwareInterface>
      <mechanicalReduction>1</mechanicalReduction>
    </actuator>
  </transmission>
  <transmission name="r_upper_arm_roll_transmission">
    <type>transmission_interface/SimpleTransmission</type>
    <joint name="r_upper_arm_roll_joint">
      <hardwareInterface>hardware_interface/PositionJointInterface</hardwareInterface>
    </joint>
    <actuator name="r_upper_arm_roll_motor">
      <hardwareInterface>hardware_interface/PositionJointInterface</hardwareInterface>
      <mechanicalReduction>1</mechanicalReduction>
    </actuator>
  </transmission>
  <transmission name="r_elbow_flex_transmission">
    <type>transmission_interface/SimpleTransmission</type>
    <joint name="r_elbow_flex_joint">
      <hardwareInterface>hardware_interface/PositionJointInterface</hardwareInterface>
    </joint>
    <actuator name="r_elbow_flex_motor">
      <hardwareInterface>hardware_interface/PositionJointInterface</hardwareInterface>
      <mechanicalReduction>1</mechanicalReduction>
    </actuator>
  </transmission>
  <gazebo reference="r_shoulder_base_link">
    <material>Gazebo/Grey</material>
  </gazebo>
  <gazebo reference="r_shoulder_link">
    <material>Gazebo/Grey</material>
  </gazebo>
  <gazebo reference="r_bicep_link">
    <material>Gazebo/Grey</material>
  </gazebo>
  <gazebo reference="r_forearm_link">
    <material>Gazebo/Grey</material>
  </gazebo>
  <link name="l_shoulder_base_link">
    <visual>
      <geometry>
        <mesh filename="package://inmoov_description/meshes/l_shoulder_base.stl" scale="0.001 0.001 0.001"/>
      </geometry>
      <origin rpy="0.0 0.0 0.0" xyz="0.0 0.0 0.0"/>
      <material name="cframe">
        <color rgba="0.90 0.90 0.90 1.0"/>
      </material>
    </visual>
    <inertial>
      <mass value="266.52696875"/>
      <inertia ixx="0.35041024" ixy="0.0057351615" ixz="-0.011193821" iyy="0.390885728" iyz="-0.045447508" izz="0.27145872"/>
    </inertial>
  </link>
  <link name="l_shoulder_link">
    <visual>
      <geometry>
        <mesh filename="package://inmoov_description/meshes/l_shoulder.stl" scale="0.001 0.001 0.001"/>
      </geometry>
      <origin rpy="0.0 0.0 0.0" xyz="0.0 0.0 0.0"/>
      <material name="cframe">
        <color rgba="0.90 0.90 0.90 1.0"/>
      </material>
    </visual>
    <inertial>
      <mass value="322.44334375"/>
      <inertia ixx="0.601346048" ixy="-0.003437744" ixz="-0.011761914" iyy="0.473865952" iyz="0.11427704" izz="0.50095152"/>
    </inertial>
  </link>
  <link name="l_bicep_link">
    <visual>
      <geometry>
        <mesh filename="package://inmoov_description/meshes/bicep.stl" scale="0.001 0.001 0.001"/>
      </geometry>
      <origin rpy="0.0 0.0 0.0" xyz="0.0 0.0 0.0"/>
      <material name="cframe">
        <color rgba="0.90 0.90 0.90 1.0"/>
      </material>
    </visual>
    <inertial>
      <mass value="281.91265625"/>
      <inertia ixx="1.283355392" ixy="-0.000200782203125" ixz="-0.224559104" iyy="1.399255168" iyz="0.0006545236875" izz="0.416621216"/>
    </inertial>
  </link>
  <link name="l_forearm_link">
    <visual>
      <geometry>
        <mesh filename="package://inmoov_description/meshes/l_forearm.stl" scale="0.001 0.001 0.001"/>
      </geometry>
      <origin rpy="0.0 0.0 0.0" xyz="0.0 0.0 0.0"/>
      <material name="cframe">
        <color rgba="0.90 0.90 0.90 1.0"/>
      </material>
    </visual>
    <inertial>
      <mass value="401.76659375"/>
      <inertia ixx="3.242308096" ixy="-0.050011216" ixz="-0.143185152" iyy="3.242510848" iyz="-0.086288992" izz="0.58458784"/>
    </inertial>
  </link>
  <joint name="l_shoulder_lift_joint" type="revolute">
    <axis xyz="0.0 -1.0 0.0"/>
    <limit effort="1000.0" lower="-1.0" upper="1.0" velocity="1.0"/>
    <parent link="l_shoulder_base_link"/>
    <child link="l_shoulder_link"/>
    <origin rpy="0.0 0.0 0.0" xyz="0.0 0.012 -0.04"/>
  </joint>
  <joint name="l_upper_arm_roll_joint" type="revolute">
    <axis xyz="0.0 0.0 -1"/>
    <limit effort="1000.0" lower="-1.0" upper="1.0" velocity="1.0"/>
    <parent link="l_shoulder_link"/>
    <child link="l_bicep_link"/>
    <origin rpy="0.0 0.0 0.0" xyz="0.0 0.066 -0.060"/>
  </joint>
  <joint name="l_elbow_flex_joint" type="revolute">
    <axis xyz="0.0 -1.0 0.0"/>
    <limit effort="1000.0" lower="0.0" upper="1.0" velocity="1.0"/>
    <parent link="l_bicep_link"/>
    <child link="l_forearm_link"/>
    <origin rpy="0.0 0.0 0.0" xyz="-0.0278 0.0 -0.2235"/>
  </joint>
  <transmission name="l_shoulder_lift_transmission">
    <type>transmission_interface/SimpleTransmission</type>
    <joint name="l_shoulder_lift_joint">
      <hardwareInterface>hardware_interface/PositionJointInterface</hardwareInterface>
    </joint>
    <actuator name="l_shoulder_lift_motor">
      <hardwareInterface>hardware_interface/PositionJointInterface</hardwareInterface>
      <mechanicalReduction>1</mechanicalReduction>
    </actuator>
  </transmission>
  <transmission name="l_upper_arm_roll_transmission">
    <type>transmission_interface/SimpleTransmission</type>
    <joint name="l_upper_arm_roll_joint">
      <hardwareInterface>hardware_interface/PositionJointInterface</hardwareInterface>
    </joint>
    <actuator name="l_upper_arm_roll_motor">
      <hardwareInterface>hardware_interface/PositionJointInterface</hardwareInterface>
      <mechanicalReduction>1</mechanicalReduction>
    </actuator>
  </transmission>
  <transmission name="l_elbow_flex_transmission">
    <type>transmission_interface/SimpleTransmission</type>
    <joint name="l_elbow_flex_joint">
      <hardwareInterface>hardware_interface/PositionJointInterface</hardwareInterface>
    </joint>
    <actuator name="l_elbow_flex_motor">
      <hardwareInterface>hardware_interface/PositionJointInterface</hardwareInterface>
      <mechanicalReduction>1</mechanicalReduction>
    </actuator>
  </transmission>
  <gazebo reference="l_shoulder_base_link">
    <material>Gazebo/Grey</material>
  </gazebo>
  <gazebo reference="l_shoulder_link">
    <material>Gazebo/Grey</material>
  </gazebo>
  <gazebo reference="l_bicep_link">
    <material>Gazebo/Grey</material>
  </gazebo>
  <gazebo reference="l_forearm_link">
    <material>Gazebo/Grey</material>
  </gazebo>
  <link name="r_hand_base_link">
    <visual>
      <geometry>
        <mesh filename="package://inmoov_description/meshes/r_hand.stl" scale="0.001 0.001 0.001"/>
      </geometry>
      <origin rpy="0.0 0.0 0.0" xyz="0.0 0.0 0.0"/>
      <material name="cframe">
        <color rgba="0.90 0.90 0.90 1.0"/>
      </material>
    </visual>
    <inertial>
      <mass value="83.605"/>
      <inertia ixx="0.126485184" ixy="6.837660156e-06" ixz="-0.000139862265625" iyy="0.094925672" iyz="0.023795198" izz="0.037456164"/>
    </inertial>
  </link>
  <link name="r_thumb1_link">
    <visual>
      <geometry>
        <mesh filename="package://inmoov_description/meshes/r_thumb5_1.stl" scale="0.001 0.001 0.001"/>
      </geometry>
      <origin rpy="0.0 0.0 0.0" xyz="0.0 0.0 0.0"/>
      <material name="cframe">
        <color rgba="0.90 0.90 0.90 1.0"/>
      </material>
    </visual>
    <inertial>
      <mass value="10.044436523"/>
      <inertia ixx="0.001744373375" ixy="-4.0159230469e-05" ixz="4.101596875e-05" iyy="0.001225091875" iyz="0.00024317490625" izz="0.0011855675"/>
    </inertial>
  </link>
  <link name="r_thumb2_link">
    <visual>
      <geometry>
        <mesh filename="package://inmoov_description/meshes/thumb5_2.stl" scale="0.001 0.001 0.001"/>
      </geometry>
      <origin rpy="0.0 0.0 0.0" xyz="0.0 0.0 0.0"/>
      <material name="cframe">
        <color rgba="0.90 0.90 0.90 1.0"/>
      </material>
    </visual>
    <inertial>
      <mass value="7.511052246"/>
      <inertia ixx="0.0013042445" ixy="2.49766266e-07" ixz="4.229196289e-06" iyy="0.001169623125" iyz="9.06593506e-07" izz="0.000555691125"/>
    </inertial>
  </link>
  <link name="r_thumb3_link">
    <visual>
      <geometry>
        <mesh filename="package://inmoov_description/meshes/thumb5_3.stl" scale="0.001 0.001 0.001"/>
      </geometry>
      <origin rpy="0.0 0.0 0.0" xyz="0.0 0.0 0.0"/>
      <material name="cframe">
        <color rgba="0.90 0.90 0.90 1.0"/>
      </material>
    </visual>
    <inertial>
      <mass value="5.81254541"/>
      <inertia ixx="0.0007149901875" ixy="-4.4194165e-07" ixz="-5.5290855469e-05" iyy="0.00073545675" iyz="4.97618683e-07" izz="0.00026050759375"/>
    </inertial>
  </link>
  <link name="r_index1_link">
    <visual>
      <geometry>
        <mesh filename="package://inmoov_description/meshes/index3_1.stl" scale="0.001 0.001 0.001"/>
      </geometry>
      <origin rpy="0.0 0.0 0.0" xyz="0.0 0.0 0.0"/>
      <material name="cframe">
        <color rgba="0.90 0.90 0.90 1.0"/>
      </material>
    </visual>
    <inertial>
      <mass value="4.854550781"/>
      <inertia ixx="0.0007855188125" ixy="-1.13786087e-07" ixz="1.2465399414e-05" iyy="0.0007367950625" iyz="1.496518921e-06" izz="0.000226730125"/>
    </inertial>
  </link>
  <link name="r_index2_link">
    <visual>
      <geometry>
        <mesh filename="package://inmoov_description/meshes/index3_2.stl" scale="0.001 0.001 0.001"/>
      </geometry>
      <origin rpy="0.0 0.0 0.0" xyz="0.0 0.0 0.0"/>
      <material name="cframe">
        <color rgba="0.90 0.90 0.90 1.0"/>
      </material>
    </visual>
    <inertial>
      <mass value="2.911548828"/>
      <inertia ixx="0.0002476975625" ixy="5.310544e-09" ixz="-1.3615135742e-05" iyy="0.0002445083125" iyz="7.01601379e-07" izz="9.1051476562e-05"/>
    </inertial>
  </link>
  <link name="r_index3_link">
    <visual>
      <geometry>
        <mesh filename="package://inmoov_description/meshes/index3_3.stl" scale="0.001 0.001 0.001"/>
      </geometry>
      <origin rpy="0.0 0.0 0.0" xyz="0.0 0.0 0.0"/>
      <material name="cframe">
        <color rgba="0.90 0.90 0.90 1.0"/>
      </material>
    </visual>
    <inertial>
      <mass value="2.754759033"/>
      <inertia ixx="0.000240287703125" ixy="2.6071491e-08" ixz="-1.3973435547e-05" iyy="0.000244506625" iyz="8.4088615e-08" izz="7.2536453125e-05"/>
    </inertial>
  </link>
  <link name="r_middle1_link">
    <visual>
      <geometry>
        <mesh filename="package://inmoov_description/meshes/middle3_1.stl" scale="0.001 0.001 0.001"/>
      </geometry>
      <origin rpy="0.0 0.0 0.0" xyz="0.0 0.0 0.0"/>
      <material name="cframe">
        <color rgba="0.90 0.90 0.90 1.0"/>
      </material>
    </visual>
    <inertial>
      <mass value="5.988140625"/>
      <inertia ixx="0.00111485875" ixy="-2.6224279e-08" ixz="1.7385302734e-05" iyy="0.00104555775" iyz="1.371758545e-06" izz="0.0003216090625"/>
    </inertial>
  </link>
  <link name="r_middle2_link">
    <visual>
      <geometry>
        <mesh filename="package://inmoov_description/meshes/middle3_2.stl" scale="0.001 0.001 0.001"/>
      </geometry>
      <origin rpy="0.0 0.0 0.0" xyz="0.0 0.0 0.0"/>
      <material name="cframe">
        <color rgba="0.90 0.90 0.90 1.0"/>
      </material>
    </visual>
    <inertial>
      <mass value="3.588543701"/>
      <inertia ixx="0.00035095146875" ixy="1.9666632e-08" ixz="-1.9434296875e-05" iyy="0.000346446375" iyz="1.214759033e-06" izz="0.000129022828125"/>
    </inertial>
  </link>
  <link name="r_middle3_link">
    <visual>
      <geometry>
        <mesh filename="package://inmoov_description/meshes/middle3_3.stl" scale="0.001 0.001 0.001"/>
      </geometry>
      <origin rpy="0.0 0.0 0.0" xyz="0.0 0.0 0.0"/>
      <material name="cframe">
        <color rgba="0.90 0.90 0.90 1.0"/>
      </material>
    </visual>
    <inertial>
      <mass value="3.395293457"/>
      <inertia ixx="0.00034045084375" ixy="3.217115e-08" ixz="-1.9707763672e-05" iyy="0.00034641909375" iyz="2.6280695e-08" izz="0.00010276375"/>
    </inertial>
  </link>
  <link name="r_ring1_link">
    <visual>
      <geometry>
        <mesh filename="package://inmoov_description/meshes/r_ring3_1.stl" scale="0.001 0.001 0.001"/>
      </geometry>
      <origin rpy="0.0 0.0 0.0" xyz="0.0 0.0 0.0"/>
      <material name="cframe">
        <color rgba="0.90 0.90 0.90 1.0"/>
      </material>
    </visual>
    <inertial>
      <mass value="10.81030957"/>
      <inertia ixx="0.0023923495" ixy="2.5959337891e-05" ixz="1.8166240234e-05" iyy="0.001249956375" iyz="-0.000426506625" izz="0.001810718375"/>
    </inertial>
  </link>
  <link name="r_ring2_link">
    <visual>
      <geometry>
        <mesh filename="package://inmoov_description/meshes/ring3_2.stl" scale="0.001 0.001 0.001"/>
      </geometry>
      <origin rpy="0.0 0.0 0.0" xyz="0.0 0.0 0.0"/>
      <material name="cframe">
        <color rgba="0.90 0.90 0.90 1.0"/>
      </material>
    </visual>
    <inertial>
      <mass value="4.222559082"/>
      <inertia ixx="0.0006227740625" ixy="5.753471e-09" ixz="1.0004874023e-05" iyy="0.0005840455625" iyz="7.29796631e-07" izz="0.000179666234375"/>
    </inertial>
  </link>
  <link name="r_ring3_link">
    <visual>
      <geometry>
        <mesh filename="package://inmoov_description/meshes/ring3_3.stl" scale="0.001 0.001 0.001"/>
      </geometry>
      <origin rpy="0.0 0.0 0.0" xyz="0.0 0.0 0.0"/>
      <material name="cframe">
        <color rgba="0.90 0.90 0.90 1.0"/>
      </material>
    </visual>
    <inertial>
      <mass value="2.530003662"/>
      <inertia ixx="0.000195998" ixy="1.0986977e-08" ixz="-1.0853751953e-05" iyy="0.00019348203125" iyz="6.78437927e-07" izz="7.2056179688e-05"/>
    </inertial>
  </link>
  <link name="r_ring4_link">
    <visual>
      <geometry>
        <mesh filename="package://inmoov_description/meshes/ring3_4.stl" scale="0.001 0.001 0.001"/>
      </geometry>
      <origin rpy="0.0 0.0 0.0" xyz="0.0 0.0 0.0"/>
      <material name="cframe">
        <color rgba="0.90 0.90 0.90 1.0"/>
      </material>
    </visual>
    <inertial>
      <mass value="2.393758301"/>
      <inertia ixx="0.000190133796875" ixy="1.7969458e-08" ixz="-1.1006313477e-05" iyy="0.0001934669375" iyz="1.4700538e-08" izz="5.7391125e-05"/>
    </inertial>
  </link>
  <link name="r_pinky1_link">
    <visual>
      <geometry>
        <mesh filename="package://inmoov_description/meshes/r_pinky3_1.stl" scale="0.001 0.001 0.001"/>
      </geometry>
      <origin rpy="0.0 0.0 0.0" xyz="0.0 0.0 0.0"/>
      <material name="cframe">
        <color rgba="0.90 0.90 0.90 1.0"/>
      </material>
    </visual>
    <inertial>
      <mass value="14.892949219"/>
      <inertia ixx="0.0043610115" ixy="3.6622980469e-05" ixz="2.9569984375e-05" iyy="0.00215359975" iyz="-0.001214404375" izz="0.003112752"/>
    </inertial>
  </link>
  <link name="r_pinky2_link">
    <visual>
      <geometry>
        <mesh filename="package://inmoov_description/meshes/pinky3_2.stl" scale="0.001 0.001 0.001"/>
      </geometry>
      <origin rpy="0.0 0.0 0.0" xyz="0.0 0.0 0.0"/>
      <material name="cframe">
        <color rgba="0.90 0.90 0.90 1.0"/>
      </material>
    </visual>
    <inertial>
      <mass value="3.053924072"/>
      <inertia ixx="0.00036256315625" ixy="-3.0389627e-08" ixz="5.979022461e-06" iyy="0.00033987203125" iyz="6.57904663e-07" izz="0.00010569428125"/>
    </inertial>
  </link>
  <link name="r_pinky3_link">
    <visual>
      <geometry>
        <mesh filename="package://inmoov_description/meshes/pinky3_3.stl" scale="0.001 0.001 0.001"/>
      </geometry>
      <origin rpy="0.0 0.0 0.0" xyz="0.0 0.0 0.0"/>
      <material name="cframe">
        <color rgba="0.90 0.90 0.90 1.0"/>
      </material>
    </visual>
    <inertial>
      <mass value="1.84870752"/>
      <inertia ixx="0.000116124148438" ixy="1.6077593e-08" ixz="-6.393164551e-06" iyy="0.000114666492188" iyz="3.92228394e-07" izz="4.2715207031e-05"/>
    </inertial>
  </link>
  <link name="r_pinky4_link">
    <visual>
      <geometry>
        <mesh filename="package://inmoov_description/meshes/pinky3_4.stl" scale="0.001 0.001 0.001"/>
      </geometry>
      <origin rpy="0.0 0.0 0.0" xyz="0.0 0.0 0.0"/>
      <material name="cframe">
        <color rgba="0.90 0.90 0.90 1.0"/>
      </material>
    </visual>
    <inertial>
      <mass value="1.748221436"/>
      <inertia ixx="0.000112612445312" ixy="1.0655196e-08" ixz="-6.518796875e-06" iyy="0.00011458659375" iyz="8.84516e-09" izz="3.3991617188e-05"/>
    </inertial>
  </link>
  <joint name="r_thumb1_joint" type="revolute">
    <axis xyz="0.0 0.0 1.0"/>
    <limit effort="1000.0" lower="0.0" upper="1.0" velocity="1.0"/>
    <parent link="r_hand_base_link"/>
    <child link="r_thumb1_link"/>
    <origin rpy="0.1 0.0 0.0" xyz="0.0 0.029 -0.0577"/>
    <mimic joint="r_thumb_joint" multiplier="0.75" offset="0.0"/>
  </joint>
  <joint name="r_thumb_joint" type="revolute">
    <axis xyz="0.0 1.0 0.0"/>
    <limit effort="1000.0" lower="0.0" upper="1.0" velocity="1.0"/>
    <parent link="r_thumb1_link"/>
    <child link="r_thumb2_link"/>
    <origin rpy="0.825 -0.1 0.3" xyz="-0.00052 0.02725 -0.013"/>
  </joint>
  <joint name="r_thumb3_joint" type="revolute">
    <axis xyz="0.0 1.0 0.0"/>
    <limit effort="1000.0" lower="0.0" upper="1.0" velocity="1.0"/>
    <parent link="r_thumb2_link"/>
    <child link="r_thumb3_link"/>
    <origin rpy="0.0 0.0 0.0" xyz="0.0 0.0 -0.035"/>
    <mimic joint="r_thumb_joint" multiplier="1.0" offset="0.0"/>
  </joint>
  <joint name="r_index1_joint" type="revolute">
    <axis xyz="0.0 1.0 0.0"/>
    <limit effort="1000.0" lower="0.0" upper="1.0" velocity="1.0"/>
    <parent link="r_hand_base_link"/>
    <child link="r_index1_link"/>
    <origin rpy="0.1 0.0 0.0" xyz="-0.0015 0.0342 -0.119"/>
    <mimic joint="r_index_joint" multiplier="1.0" offset="0.0"/>
  </joint>
  <joint name="r_index_joint" type="revolute">
    <axis xyz="0.0 1.0 0.0"/>
    <limit effort="1000.0" lower="0.0" upper="1.0" velocity="1.0"/>
    <parent link="r_index1_link"/>
    <child link="r_index2_link"/>
    <origin rpy="0.0 0.0 0.0" xyz="0.0 0.001 -0.03595"/>
  </joint>
  <joint name="r_index3_joint" type="revolute">
    <axis xyz="0.0 1.0 0.0"/>
    <limit effort="1000.0" lower="0.0" upper="1.0" velocity="1.0"/>
    <parent link="r_index2_link"/>
    <child link="r_index3_link"/>
    <origin rpy="0.0 0.0 0.0" xyz="0.0 0.0 -0.024"/>
    <mimic joint="r_index_joint" multiplier="1.0" offset="0.0"/>
  </joint>
  <joint name="r_middle1_joint" type="revolute">
    <axis xyz="0.0 1.0 0.0"/>
    <limit effort="1000.0" lower="0.0" upper="1.0" velocity="1.0"/>
    <parent link="r_hand_base_link"/>
    <child link="r_middle1_link"/>
    <origin rpy="0.0 0.0 0.0" xyz="-0.00175 0.007 -0.12325"/>
    <mimic joint="r_middle_joint" multiplier="1.0" offset="0.0"/>
  </joint>
  <joint name="r_middle_joint" type="revolute">
    <axis xyz="0.0 1.0 0.0"/>
    <limit effort="1000.0" lower="0.0" upper="1.0" velocity="1.0"/>
    <parent link="r_middle1_link"/>
    <child link="r_middle2_link"/>
    <origin rpy="0.0 0.0 0.0" xyz="0.0 0.0 -0.0389"/>
  </joint>
  <joint name="r_middle3_joint" type="revolute">
    <axis xyz="0.0 1.0 0.0"/>
    <limit effort="1000.0" lower="0.0" upper="1.0" velocity="1.0"/>
    <parent link="r_middle2_link"/>
    <child link="r_middle3_link"/>
    <origin rpy="0.0 0.0 0.0" xyz="0.0 0.0005 -0.0259"/>
    <mimic joint="r_middle_joint" multiplier="1.0" offset="0.0"/>
  </joint>
  <joint name="r_ring1_joint" type="revolute">
    <axis xyz="0.0 0.0 1.0"/>
    <limit effort="1000.0" lower="0.0" upper="1.0" velocity="1.0"/>
    <parent link="r_hand_base_link"/>
    <child link="r_ring1_link"/>
    <origin rpy="0.7 0.0 0.0" xyz="0.0 -0.00705 -0.0794"/>
    <mimic joint="r_ring_joint" multiplier="-0.1" offset="0.0"/>
  </joint>
  <joint name="r_ring_joint" type="revolute">
    <axis xyz="0.0 1.0 0.0"/>
    <limit effort="1000.0" lower="0.0" upper="1.0" velocity="1.0"/>
    <parent link="r_ring1_link"/>
    <child link="r_ring2_link"/>
    <origin rpy="-0.7775 0.0 0.0" xyz="0.00126 -0.0351 -0.0166"/>
  </joint>
  <joint name="r_ring3_joint" type="revolute">
    <axis xyz="0.0 1.0 0.0"/>
    <limit effort="1000.0" lower="0.0" upper="1.0" velocity="1.0"/>
    <parent link="r_ring2_link"/>
    <child link="r_ring3_link"/>
    <origin rpy="0.0 0.0 0.0" xyz="0.0 0.0005 -0.0345"/>
    <mimic joint="r_ring_joint" multiplier="1.0" offset="0.0"/>
  </joint>
  <joint name="r_ring4_joint" type="revolute">
    <axis xyz="0.0 1.0 0.0"/>
    <limit effort="1000.0" lower="0.0" upper="1.0" velocity="1.0"/>
    <parent link="r_ring3_link"/>
    <child link="r_ring4_link"/>
    <origin rpy="0.0 0.0 0.0" xyz="0.0 0.0004 -0.0229"/>
    <mimic joint="r_ring_joint" multiplier="1.0" offset="0.0"/>
  </joint>
  <joint name="r_pinky1_joint" type="revolute">
    <axis xyz="0.0 0.0 1.0"/>
    <limit effort="1000.0" lower="0.0" upper="1.0" velocity="1.0"/>
    <parent link="r_hand_base_link"/>
    <child link="r_pinky1_link"/>
    <origin rpy="0.7 0.0 0.0" xyz="0.0 -0.027 -0.0555"/>
    <mimic joint="r_pinky_joint" multiplier="-0.1" offset="0.0"/>
  </joint>
  <joint name="r_pinky_joint" type="revolute">
    <axis xyz="0.0 1.0 0.0"/>
    <limit effort="1000.0" lower="0.0" upper="1.0" velocity="1.0"/>
    <parent link="r_pinky1_link"/>
    <child link="r_pinky2_link"/>
    <origin rpy="-0.93 0.0 0.0" xyz="0.0 -0.046 -0.0228"/>
  </joint>
  <joint name="r_pinky3_joint" type="revolute">
    <axis xyz="0.0 1.0 0.0"/>
    <limit effort="1000.0" lower="0.0" upper="1.0" velocity="1.0"/>
    <parent link="r_pinky2_link"/>
    <child link="r_pinky3_link"/>
    <origin rpy="0.0 0.0 0.0" xyz="0.0 0.0005 -0.031"/>
    <mimic joint="r_pinky_joint" multiplier="1.0" offset="0.0"/>
  </joint>
  <joint name="r_pinky4_joint" type="revolute">
    <axis xyz="0.0 1.0 0.0"/>
    <limit effort="1000.0" lower="0.0" upper="1.0" velocity="1.0"/>
    <parent link="r_pinky3_link"/>
    <child link="r_pinky4_link"/>
    <origin rpy="0.0 0.0 0.0" xyz="0.0 0.0004 -0.0208"/>
    <mimic joint="r_pinky_joint" multiplier="1.0" offset="0.0"/>
  </joint>
  <transmission name="r_thumb_transmission">
    <type>transmission_interface/SimpleTransmission</type>
    <joint name="r_thumb_joint">
      <hardwareInterface>hardware_interface/PositionJointInterface</hardwareInterface>
    </joint>
    <actuator name="r_thumb_motor">
      <hardwareInterface>hardware_interface/PositionJointInterface</hardwareInterface>
      <mechanicalReduction>1</mechanicalReduction>
    </actuator>
  </transmission>
  <transmission name="r_index_transmission">
    <type>transmission_interface/SimpleTransmission</type>
    <joint name="r_index_joint">
      <hardwareInterface>hardware_interface/PositionJointInterface</hardwareInterface>
    </joint>
    <actuator name="r_index_motor">
      <hardwareInterface>hardware_interface/PositionJointInterface</hardwareInterface>
      <mechanicalReduction>1</mechanicalReduction>
    </actuator>
  </transmission>
  <transmission name="r_middle_transmission">
    <type>transmission_interface/SimpleTransmission</type>
    <joint name="r_middle_joint">
      <hardwareInterface>hardware_interface/PositionJointInterface</hardwareInterface>
    </joint>
    <actuator name="r_middle_motor">
      <hardwareInterface>hardware_interface/PositionJointInterface</hardwareInterface>
      <mechanicalReduction>1</mechanicalReduction>
    </actuator>
  </transmission>
  <transmission name="r_ring_transmission">
    <type>transmission_interface/SimpleTransmission</type>
    <joint name="r_ring_joint">
      <hardwareInterface>hardware_interface/PositionJointInterface</hardwareInterface>
    </joint>
    <actuator name="r_ring_motor">
      <hardwareInterface>hardware_interface/PositionJointInterface</hardwareInterface>
      <mechanicalReduction>1</mechanicalReduction>
    </actuator>
  </transmission>
  <transmission name="r_pinky_transmission">
    <type>transmission_interface/SimpleTransmission</type>
    <joint name="r_pinky_joint">
      <hardwareInterface>hardware_interface/PositionJointInterface</hardwareInterface>
    </joint>
    <actuator name="r_pinky_motor">
      <hardwareInterface>hardware_interface/PositionJointInterface</hardwareInterface>
      <mechanicalReduction>1</mechanicalReduction>
    </actuator>
  </transmission>
  <gazebo reference="r_hand_base_link">
    <material>Gazebo/Grey</material>
  </gazebo>
  <gazebo reference="r_thumb1_link">
    <material>Gazebo/Grey</material>
  </gazebo>
  <gazebo reference="r_thumb2_link">
    <material>Gazebo/Grey</material>
  </gazebo>
  <gazebo reference="r_thumb3_link">
    <material>Gazebo/Grey</material>
  </gazebo>
  <gazebo reference="r_index1_link">
    <material>Gazebo/Grey</material>
  </gazebo>
  <gazebo reference="r_index2_link">
    <material>Gazebo/Grey</material>
  </gazebo>
  <gazebo reference="r_index3_link">
    <material>Gazebo/Grey</material>
  </gazebo>
  <gazebo reference="r_middle1_link">
    <material>Gazebo/Grey</material>
  </gazebo>
  <gazebo reference="r_middle2_link">
    <material>Gazebo/Grey</material>
  </gazebo>
  <gazebo reference="r_middle3_link">
    <material>Gazebo/Grey</material>
  </gazebo>
  <gazebo reference="r_ring1_link">
    <material>Gazebo/Grey</material>
  </gazebo>
  <gazebo reference="r_ring2_link">
    <material>Gazebo/Grey</material>
  </gazebo>
  <gazebo reference="r_ring3_link">
    <material>Gazebo/Grey</material>
  </gazebo>
  <gazebo reference="r_ring4_link">
    <material>Gazebo/Grey</material>
  </gazebo>
  <gazebo reference="r_pinky1_link">
    <material>Gazebo/Grey</material>
  </gazebo>
  <gazebo reference="r_pinky2_link">
    <material>Gazebo/Grey</material>
  </gazebo>
  <gazebo reference="r_pinky3_link">
    <material>Gazebo/Grey</material>
  </gazebo>
  <gazebo reference="r_pinky4_link">
    <material>Gazebo/Grey</material>
  </gazebo>
  <link name="l_hand_base_link">
    <visual>
      <geometry>
        <mesh filename="package://inmoov_description/meshes/l_hand.stl" scale="0.001 0.001 0.001"/>
      </geometry>
      <origin rpy="0.0 0.0 0.0" xyz="0.0 0.0 0.0"/>
      <material name="cframe">
        <color rgba="0.90 0.90 0.90 1.0"/>
      </material>
    </visual>
    <inertial>
      <mass value="83.605007812"/>
      <inertia ixx="0.126485224" ixy="-6.832961426e-06" ixz="-0.000139859234375" iyy="0.094925688" iyz="-0.023795198" izz="0.037456156"/>
    </inertial>
  </link>
  <link name="l_thumb1_link">
    <visual>
      <geometry>
        <mesh filename="package://inmoov_description/meshes/l_thumb5_1.stl" scale="0.001 0.001 0.001"/>
      </geometry>
      <origin rpy="0.0 0.0 0.0" xyz="0.0 0.0 0.0"/>
      <material name="cframe">
        <color rgba="0.90 0.90 0.90 1.0"/>
      </material>
    </visual>
    <inertial>
      <mass value="10.0444375"/>
      <inertia ixx="0.001744373625" ixy="4.0159183594e-05" ixz="4.1015949219e-05" iyy="0.001225092125" iyz="-0.000243175015625" izz="0.001185567625"/>
    </inertial>
  </link>
  <link name="l_thumb2_link">
    <visual>
      <geometry>
        <mesh filename="package://inmoov_description/meshes/thumb5_2.stl" scale="0.001 0.001 0.001"/>
      </geometry>
      <origin rpy="0.0 0.0 0.0" xyz="0.0 0.0 0.0"/>
      <material name="cframe">
        <color rgba="0.90 0.90 0.90 1.0"/>
      </material>
    </visual>
    <inertial>
      <mass value="7.511052246"/>
      <inertia ixx="0.0013042445" ixy="2.49766266e-07" ixz="4.229196289e-06" iyy="0.001169623125" iyz="9.06593506e-07" izz="0.000555691125"/>
    </inertial>
  </link>
  <link name="l_thumb3_link">
    <visual>
      <geometry>
        <mesh filename="package://inmoov_description/meshes/thumb5_3.stl" scale="0.001 0.001 0.001"/>
      </geometry>
      <origin rpy="0.0 0.0 0.0" xyz="0.0 0.0 0.0"/>
      <material name="cframe">
        <color rgba="0.90 0.90 0.90 1.0"/>
      </material>
    </visual>
    <inertial>
      <mass value="5.81254541"/>
      <inertia ixx="0.0007149901875" ixy="-4.4194165e-07" ixz="-5.5290855469e-05" iyy="0.00073545675" iyz="4.97618683e-07" izz="0.00026050759375"/>
    </inertial>
  </link>
  <link name="l_index1_link">
    <visual>
      <geometry>
        <mesh filename="package://inmoov_description/meshes/index3_1.stl" scale="0.001 0.001 0.001"/>
      </geometry>
      <origin rpy="0.0 0.0 0.0" xyz="0.0 0.0 0.0"/>
      <material name="cframe">
        <color rgba="0.90 0.90 0.90 1.0"/>
      </material>
    </visual>
    <inertial>
      <mass value="4.854550781"/>
      <inertia ixx="0.0007855188125" ixy="-1.13786087e-07" ixz="1.2465399414e-05" iyy="0.0007367950625" iyz="1.496518921e-06" izz="0.000226730125"/>
    </inertial>
  </link>
  <link name="l_index2_link">
    <visual>
      <geometry>
        <mesh filename="package://inmoov_description/meshes/index3_2.stl" scale="0.001 0.001 0.001"/>
      </geometry>
      <origin rpy="0.0 0.0 0.0" xyz="0.0 0.0 0.0"/>
      <material name="cframe">
        <color rgba="0.90 0.90 0.90 1.0"/>
      </material>
    </visual>
    <inertial>
      <mass value="2.911548828"/>
      <inertia ixx="0.0002476975625" ixy="5.310544e-09" ixz="-1.3615135742e-05" iyy="0.0002445083125" iyz="7.01601379e-07" izz="9.1051476562e-05"/>
    </inertial>
  </link>
  <link name="l_index3_link">
    <visual>
      <geometry>
        <mesh filename="package://inmoov_description/meshes/index3_3.stl" scale="0.001 0.001 0.001"/>
      </geometry>
      <origin rpy="0.0 0.0 0.0" xyz="0.0 0.0 0.0"/>
      <material name="cframe">
        <color rgba="0.90 0.90 0.90 1.0"/>
      </material>
    </visual>
    <inertial>
      <mass value="2.754759033"/>
      <inertia ixx="0.000240287703125" ixy="2.6071491e-08" ixz="-1.3973435547e-05" iyy="0.000244506625" iyz="8.4088615e-08" izz="7.2536453125e-05"/>
    </inertial>
  </link>
  <link name="l_middle1_link">
    <visual>
      <geometry>
        <mesh filename="package://inmoov_description/meshes/middle3_1.stl" scale="0.001 0.001 0.001"/>
      </geometry>
      <origin rpy="0.0 0.0 0.0" xyz="0.0 0.0 0.0"/>
      <material name="cframe">
        <color rgba="0.90 0.90 0.90 1.0"/>
      </material>
    </visual>
    <inertial>
      <mass value="5.988140625"/>
      <inertia ixx="0.00111485875" ixy="-2.6224279e-08" ixz="1.7385302734e-05" iyy="0.00104555775" iyz="1.371758545e-06" izz="0.0003216090625"/>
    </inertial>
  </link>
  <link name="l_middle2_link">
    <visual>
      <geometry>
        <mesh filename="package://inmoov_description/meshes/middle3_2.stl" scale="0.001 0.001 0.001"/>
      </geometry>
      <origin rpy="0.0 0.0 0.0" xyz="0.0 0.0 0.0"/>
      <material name="cframe">
        <color rgba="0.90 0.90 0.90 1.0"/>
      </material>
    </visual>
    <inertial>
      <mass value="3.588543701"/>
      <inertia ixx="0.00035095146875" ixy="1.9666632e-08" ixz="-1.9434296875e-05" iyy="0.000346446375" iyz="1.214759033e-06" izz="0.000129022828125"/>
    </inertial>
  </link>
  <link name="l_middle3_link">
    <visual>
      <geometry>
        <mesh filename="package://inmoov_description/meshes/middle3_3.stl" scale="0.001 0.001 0.001"/>
      </geometry>
      <origin rpy="0.0 0.0 0.0" xyz="0.0 0.0 0.0"/>
      <material name="cframe">
        <color rgba="0.90 0.90 0.90 1.0"/>
      </material>
    </visual>
    <inertial>
      <mass value="3.395293457"/>
      <inertia ixx="0.00034045084375" ixy="3.217115e-08" ixz="-1.9707763672e-05" iyy="0.00034641909375" iyz="2.6280695e-08" izz="0.00010276375"/>
    </inertial>
  </link>
  <link name="l_ring1_link">
    <visual>
      <geometry>
        <mesh filename="package://inmoov_description/meshes/l_ring3_1.stl" scale="0.001 0.001 0.001"/>
      </geometry>
      <origin rpy="0.0 0.0 0.0" xyz="0.0 0.0 0.0"/>
      <material name="cframe">
        <color rgba="0.90 0.90 0.90 1.0"/>
      </material>
    </visual>
    <inertial>
      <mass value="10.81030957"/>
      <inertia ixx="0.002392349" ixy="-2.5959347656e-05" ixz="1.8166251953e-05" iyy="0.001249956375" iyz="0.00042650671875" izz="0.0018107185"/>
    </inertial>
  </link>
  <link name="l_ring2_link">
    <visual>
      <geometry>
        <mesh filename="package://inmoov_description/meshes/ring3_2.stl" scale="0.001 0.001 0.001"/>
      </geometry>
      <origin rpy="0.0 0.0 0.0" xyz="0.0 0.0 0.0"/>
      <material name="cframe">
        <color rgba="0.90 0.90 0.90 1.0"/>
      </material>
    </visual>
    <inertial>
      <mass value="4.222559082"/>
      <inertia ixx="0.0006227740625" ixy="5.753471e-09" ixz="1.0004874023e-05" iyy="0.0005840455625" iyz="7.29796631e-07" izz="0.000179666234375"/>
    </inertial>
  </link>
  <link name="l_ring3_link">
    <visual>
      <geometry>
        <mesh filename="package://inmoov_description/meshes/ring3_3.stl" scale="0.001 0.001 0.001"/>
      </geometry>
      <origin rpy="0.0 0.0 0.0" xyz="0.0 0.0 0.0"/>
      <material name="cframe">
        <color rgba="0.90 0.90 0.90 1.0"/>
      </material>
    </visual>
    <inertial>
      <mass value="2.530003662"/>
      <inertia ixx="0.000195998" ixy="1.0986977e-08" ixz="-1.0853751953e-05" iyy="0.00019348203125" iyz="6.78437927e-07" izz="7.2056179688e-05"/>
    </inertial>
  </link>
  <link name="l_ring4_link">
    <visual>
      <geometry>
        <mesh filename="package://inmoov_description/meshes/ring3_4.stl" scale="0.001 0.001 0.001"/>
      </geometry>
      <origin rpy="0.0 0.0 0.0" xyz="0.0 0.0 0.0"/>
      <material name="cframe">
        <color rgba="0.90 0.90 0.90 1.0"/>
      </material>
    </visual>
    <inertial>
      <mass value="2.393758301"/>
      <inertia ixx="0.000190133796875" ixy="1.7969458e-08" ixz="-1.1006313477e-05" iyy="0.0001934669375" iyz="1.4700538e-08" izz="5.7391125e-05"/>
    </inertial>
  </link>
  <link name="l_pinky1_link">
    <visual>
      <geometry>
        <mesh filename="package://inmoov_description/meshes/l_pinky3_1.stl" scale="0.001 0.001 0.001"/>
      </geometry>
      <origin rpy="0.0 0.0 0.0" xyz="0.0 0.0 0.0"/>
      <material name="cframe">
        <color rgba="0.90 0.90 0.90 1.0"/>
      </material>
    </visual>
    <inertial>
      <mass value="14.892949219"/>
      <inertia ixx="0.004361011" ixy="-3.6622921875e-05" ixz="2.9569964844e-05" iyy="0.00215359975" iyz="0.001214404125" izz="0.003112752"/>
    </inertial>
  </link>
  <link name="l_pinky2_link">
    <visual>
      <geometry>
        <mesh filename="package://inmoov_description/meshes/pinky3_2.stl" scale="0.001 0.001 0.001"/>
      </geometry>
      <origin rpy="0.0 0.0 0.0" xyz="0.0 0.0 0.0"/>
      <material name="cframe">
        <color rgba="0.90 0.90 0.90 1.0"/>
      </material>
    </visual>
    <inertial>
      <mass value="3.053924072"/>
      <inertia ixx="0.00036256315625" ixy="-3.0389627e-08" ixz="5.979022461e-06" iyy="0.00033987203125" iyz="6.57904663e-07" izz="0.00010569428125"/>
    </inertial>
  </link>
  <link name="l_pinky3_link">
    <visual>
      <geometry>
        <mesh filename="package://inmoov_description/meshes/pinky3_3.stl" scale="0.001 0.001 0.001"/>
      </geometry>
      <origin rpy="0.0 0.0 0.0" xyz="0.0 0.0 0.0"/>
      <material name="cframe">
        <color rgba="0.90 0.90 0.90 1.0"/>
      </material>
    </visual>
    <inertial>
      <mass value="1.84870752"/>
      <inertia ixx="0.000116124148438" ixy="1.6077593e-08" ixz="-6.393164551e-06" iyy="0.000114666492188" iyz="3.92228394e-07" izz="4.2715207031e-05"/>
    </inertial>
  </link>
  <link name="l_pinky4_link">
    <visual>
      <geometry>
        <mesh filename="package://inmoov_description/meshes/pinky3_4.stl" scale="0.001 0.001 0.001"/>
      </geometry>
      <origin rpy="0.0 0.0 0.0" xyz="0.0 0.0 0.0"/>
      <material name="cframe">
        <color rgba="0.90 0.90 0.90 1.0"/>
      </material>
    </visual>
    <inertial>
      <mass value="1.748221436"/>
      <inertia ixx="0.000112612445312" ixy="1.0655196e-08" ixz="-6.518796875e-06" iyy="0.00011458659375" iyz="8.84516e-09" izz="3.3991617188e-05"/>
    </inertial>
  </link>
  <joint name="l_thumb1_joint" type="revolute">
    <axis xyz="0.0 0.0 1.0"/>
    <limit effort="1000.0" lower="0.0" upper="1.0" velocity="1.0"/>
    <parent link="l_hand_base_link"/>
    <child link="l_thumb1_link"/>
    <origin rpy="-0.1 0.0 0.0" xyz="0.0 -0.029 -0.0577"/>
    <mimic joint="l_thumb_joint" multiplier="-0.75" offset="0.0"/>
  </joint>
  <joint name="l_thumb_joint" type="revolute">
    <axis xyz="0.0 1.0 0.0"/>
    <limit effort="1000.0" lower="0.0" upper="1.0" velocity="1.0"/>
    <parent link="l_thumb1_link"/>
    <child link="l_thumb2_link"/>
    <origin rpy="-0.825 -0.1 -0.3" xyz="-0.00052 -0.02725 -0.013"/>
  </joint>
  <joint name="l_thumb3_joint" type="revolute">
    <axis xyz="0.0 1.0 0.0"/>
    <limit effort="1000.0" lower="0.0" upper="1.0" velocity="1.0"/>
    <parent link="l_thumb2_link"/>
    <child link="l_thumb3_link"/>
    <origin rpy="0.0 0.0 0.0" xyz="0.0 0.0 -0.035"/>
    <mimic joint="l_thumb_joint" multiplier="1.0" offset="0.0"/>
  </joint>
  <joint name="l_index1_joint" type="revolute">
    <axis xyz="0.0 1.0 0.0"/>
    <limit effort="1000.0" lower="0.0" upper="1.0" velocity="1.0"/>
    <parent link="l_hand_base_link"/>
    <child link="l_index1_link"/>
    <origin rpy="-0.1 0.0 0.0" xyz="-0.0015 -0.0342 -0.119"/>
    <mimic joint="l_index_joint" multiplier="1.0" offset="0.0"/>
  </joint>
  <joint name="l_index_joint" type="revolute">
    <axis xyz="0.0 1.0 0.0"/>
    <limit effort="1000.0" lower="0.0" upper="1.0" velocity="1.0"/>
    <parent link="l_index1_link"/>
    <child link="l_index2_link"/>
    <origin rpy="0.0 0.0 0.0" xyz="0.0 0.001 -0.03595"/>
  </joint>
  <joint name="l_index3_joint" type="revolute">
    <axis xyz="0.0 1.0 0.0"/>
    <limit effort="1000.0" lower="0.0" upper="1.0" velocity="1.0"/>
    <parent link="l_index2_link"/>
    <child link="l_index3_link"/>
    <origin rpy="0.0 0.0 0.0" xyz="0.0 0.0 -0.024"/>
    <mimic joint="l_index_joint" multiplier="1.0" offset="0.0"/>
  </joint>
  <joint name="l_middle1_joint" type="revolute">
    <axis xyz="0.0 1.0 0.0"/>
    <limit effort="1000.0" lower="0.0" upper="1.0" velocity="1.0"/>
    <parent link="l_hand_base_link"/>
    <child link="l_middle1_link"/>
    <origin rpy="0.0 0.0 0.0" xyz="-0.00175 -0.007 -0.12325"/>
    <mimic joint="l_middle_joint" multiplier="1.0" offset="0.0"/>
  </joint>
  <joint name="l_middle_joint" type="revolute">
    <axis xyz="0.0 1.0 0.0"/>
    <limit effort="1000.0" lower="0.0" upper="1.0" velocity="1.0"/>
    <parent link="l_middle1_link"/>
    <child link="l_middle2_link"/>
    <origin rpy="0.0 0.0 0.0" xyz="0.0 0.0 -0.0389"/>
  </joint>
  <joint name="l_middle3_joint" type="revolute">
    <axis xyz="0.0 1.0 0.0"/>
    <limit effort="1000.0" lower="0.0" upper="1.0" velocity="1.0"/>
    <parent link="l_middle2_link"/>
    <child link="l_middle3_link"/>
    <origin rpy="0.0 0.0 0.0" xyz="0.0 0.0005 -0.0259"/>
    <mimic joint="l_middle_joint" multiplier="1.0" offset="0.0"/>
  </joint>
  <joint name="l_ring1_joint" type="revolute">
    <axis xyz="0.0 0.0 1.0"/>
    <limit effort="1000.0" lower="0.0" upper="1.0" velocity="1.0"/>
    <parent link="l_hand_base_link"/>
    <child link="l_ring1_link"/>
    <origin rpy="-0.7 0.0 0.0" xyz="0.0 0.00705 -0.0794"/>
    <mimic joint="l_ring_joint" multiplier="0.1" offset="0.0"/>
  </joint>
  <joint name="l_ring_joint" type="revolute">
    <axis xyz="0.0 1.0 0.0"/>
    <limit effort="1000.0" lower="0.0" upper="1.0" velocity="1.0"/>
    <parent link="l_ring1_link"/>
    <child link="l_ring2_link"/>
    <origin rpy="0.7775 0.0 0.0" xyz="0.00126 0.0351 -0.0166"/>
  </joint>
  <joint name="l_ring3_joint" type="revolute">
    <axis xyz="0.0 1.0 0.0"/>
    <limit effort="1000.0" lower="0.0" upper="1.0" velocity="1.0"/>
    <parent link="l_ring2_link"/>
    <child link="l_ring3_link"/>
    <origin rpy="0.0 0.0 0.0" xyz="0.0 0.0005 -0.0345"/>
    <mimic joint="l_ring_joint" multiplier="1.0" offset="0.0"/>
  </joint>
  <joint name="l_ring4_joint" type="revolute">
    <axis xyz="0.0 1.0 0.0"/>
    <limit effort="1000.0" lower="0.0" upper="1.0" velocity="1.0"/>
    <parent link="l_ring3_link"/>
    <child link="l_ring4_link"/>
    <origin rpy="0.0 0.0 0.0" xyz="0.0 0.0004 -0.0229"/>
    <mimic joint="l_ring_joint" multiplier="1.0" offset="0.0"/>
  </joint>
  <joint name="l_pinky1_joint" type="revolute">
    <axis xyz="0.0 0.0 1.0"/>
    <limit effort="1000.0" lower="0.0" upper="1.0" velocity="1.0"/>
    <parent link="l_hand_base_link"/>
    <child link="l_pinky1_link"/>
    <origin rpy="-0.7 0.0 0.0" xyz="0.0 0.027 -0.0555"/>
    <mimic joint="l_pinky_joint" multiplier="0.1" offset="0.0"/>
  </joint>
  <joint name="l_pinky_joint" type="revolute">
    <axis xyz="0.0 1.0 0.0"/>
    <limit effort="1000.0" lower="0.0" upper="1.0" velocity="1.0"/>
    <parent link="l_pinky1_link"/>
    <child link="l_pinky2_link"/>
    <origin rpy="0.93 0.0 0.0" xyz="0.0 0.046 -0.0228"/>
  </joint>
  <joint name="l_pinky3_joint" type="revolute">
    <axis xyz="0.0 1.0 0.0"/>
    <limit effort="1000.0" lower="0.0" upper="1.0" velocity="1.0"/>
    <parent link="l_pinky2_link"/>
    <child link="l_pinky3_link"/>
    <origin rpy="0.0 0.0 0.0" xyz="0.0 0.0005 -0.031"/>
    <mimic joint="l_pinky_joint" multiplier="1.0" offset="0.0"/>
  </joint>
  <joint name="l_pinky4_joint" type="revolute">
    <axis xyz="0.0 1.0 0.0"/>
    <limit effort="1000.0" lower="0.0" upper="1.0" velocity="1.0"/>
    <parent link="l_pinky3_link"/>
    <child link="l_pinky4_link"/>
    <origin rpy="0.0 0.0 0.0" xyz="0.0 0.0004 -0.0208"/>
    <mimic joint="l_pinky_joint" multiplier="1.0" offset="0.0"/>
  </joint>
  <transmission name="l_thumb_transmission">
    <type>transmission_interface/SimpleTransmission</type>
    <joint name="l_thumb_joint">
      <hardwareInterface>hardware_interface/PositionJointInterface</hardwareInterface>
    </joint>
    <actuator name="l_thumb_motor">
      <hardwareInterface>hardware_interface/PositionJointInterface</hardwareInterface>
      <mechanicalReduction>1</mechanicalReduction>
    </actuator>
  </transmission>
  <transmission name="l_index_transmission">
    <type>transmission_interface/SimpleTransmission</type>
    <joint name="l_index_joint">
      <hardwareInterface>hardware_interface/PositionJointInterface</hardwareInterface>
    </joint>
    <actuator name="l_index_motor">
      <hardwareInterface>hardware_interface/PositionJointInterface</hardwareInterface>
      <mechanicalReduction>1</mechanicalReduction>
    </actuator>
  </transmission>
  <transmission name="l_middle_transmission">
    <type>transmission_interface/SimpleTransmission</type>
    <joint name="l_middle_joint">
      <hardwareInterface>hardware_interface/PositionJointInterface</hardwareInterface>
    </joint>
    <actuator name="l_middle_motor">
      <hardwareInterface>hardware_interface/PositionJointInterface</hardwareInterface>
      <mechanicalReduction>1</mechanicalReduction>
    </actuator>
  </transmission>
  <transmission name="l_ring_transmission">
    <type>transmission_interface/SimpleTransmission</type>
    <joint name="l_ring_joint">
      <hardwareInterface>hardware_interface/PositionJointInterface</hardwareInterface>
    </joint>
    <actuator name="l_ring_motor">
      <hardwareInterface>hardware_interface/PositionJointInterface</hardwareInterface>
      <mechanicalReduction>1</mechanicalReduction>
    </actuator>
  </transmission>
  <transmission name="l_pinky_transmission">
    <type>transmission_interface/SimpleTransmission</type>
    <joint name="l_pinky_joint">
      <hardwareInterface>hardware_interface/PositionJointInterface</hardwareInterface>
    </joint>
    <actuator name="l_pinky_motor">
      <hardwareInterface>hardware_interface/PositionJointInterface</hardwareInterface>
      <mechanicalReduction>1</mechanicalReduction>
    </actuator>
  </transmission>
  <gazebo reference="l_hand_base_link">
    <material>Gazebo/Grey</material>
  </gazebo>
  <gazebo reference="l_thumb1_link">
    <material>Gazebo/Grey</material>
  </gazebo>
  <gazebo reference="l_thumb2_link">
    <material>Gazebo/Grey</material>
  </gazebo>
  <gazebo reference="l_thumb3_link">
    <material>Gazebo/Grey</material>
  </gazebo>
  <gazebo reference="l_index1_link">
    <material>Gazebo/Grey</material>
  </gazebo>
  <gazebo reference="l_index2_link">
    <material>Gazebo/Grey</material>
  </gazebo>
  <gazebo reference="l_index3_link">
    <material>Gazebo/Grey</material>
  </gazebo>
  <gazebo reference="l_middle1_link">
    <material>Gazebo/Grey</material>
  </gazebo>
  <gazebo reference="l_middle2_link">
    <material>Gazebo/Grey</material>
  </gazebo>
  <gazebo reference="l_middle3_link">
    <material>Gazebo/Grey</material>
  </gazebo>
  <gazebo reference="l_ring1_link">
    <material>Gazebo/Grey</material>
  </gazebo>
  <gazebo reference="l_ring2_link">
    <material>Gazebo/Grey</material>
  </gazebo>
  <gazebo reference="l_ring3_link">
    <material>Gazebo/Grey</material>
  </gazebo>
  <gazebo reference="l_ring4_link">
    <material>Gazebo/Grey</material>
  </gazebo>
  <gazebo reference="l_pinky1_link">
    <material>Gazebo/Grey</material>
  </gazebo>
  <gazebo reference="l_pinky2_link">
    <material>Gazebo/Grey</material>
  </gazebo>
  <gazebo reference="l_pinky3_link">
    <material>Gazebo/Grey</material>
  </gazebo>
  <gazebo reference="l_pinky4_link">
    <material>Gazebo/Grey</material>
  </gazebo>
  <joint name="fixed" type="fixed">
    <parent link="world"/>
    <child link="base_link"/>
  </joint>
  <joint name="base_to_pedestal_joint" type="fixed">
    <parent link="base_link"/>
    <child link="pedestal_link"/>
    <origin rpy="0.0 0.0 0.0" xyz="0.0 0.0 0.0"/>
  </joint>
  <joint name="pedestal_to_top_stomach_joint" type="fixed">
    <parent link="pedestal_link"/>
    <child link="mid_stomach_link"/>
    <origin rpy="0.0 0.0 0.0" xyz="0.0 0.0 0.0"/>
  </joint>
  <joint name="r_shoulder_base_joint" type="revolute">
    <axis xyz="-1.0 0.0 0.0"/>
    <limit effort="1000.0" lower="0.0" upper="1.0" velocity="1.0"/>
    <parent link="torso_link"/>
    <child link="r_shoulder_base_link"/>
    <origin rpy="0.0 0.0 0.0" xyz="0.0 -0.143 0.298"/>
  </joint>
  <joint name="r_wrist_roll_joint" type="revolute">
    <axis xyz="0.0 0.0 -1.0"/>
    <limit effort="1000.0" lower="-1.0" upper="1.0" velocity="1.0"/>
    <parent link="r_forearm_link"/>
    <child link="r_hand_base_link"/>
    <origin rpy="0.0 0.0 0.0" xyz="-0.0144 0.01 -0.2885"/>
  </joint>
  <joint name="l_shoulder_base_joint" type="revolute">
    <axis xyz="1.0 0.0 0.0"/>
    <limit effort="1000.0" lower="0.0" upper="1.0" velocity="1.0"/>
    <parent link="torso_link"/>
    <child link="l_shoulder_base_link"/>
    <origin rpy="0.0 0.0 0.0" xyz="0.0 0.143 0.298"/>
  </joint>
  <joint name="l_wrist_roll_joint" type="revolute">
    <axis xyz="0.0 0.0 1.0"/>
    <limit effort="1000.0" lower="-1.0" upper="1.0" velocity="1.0"/>
    <parent link="l_forearm_link"/>
    <child link="l_hand_base_link"/>
    <origin rpy="0.0 0.0 0.0" xyz="-0.0144 -0.01 -0.2885"/>
  </joint>
  <transmission name="r_shoulder_base_transmission">
    <type>transmission_interface/SimpleTransmission</type>
    <joint name="r_shoulder_base_joint">
      <hardwareInterface>hardware_interface/PositionJointInterface</hardwareInterface>
    </joint>
    <actuator name="r_shoulder_base_motor">
      <hardwareInterface>hardware_interface/PositionJointInterface</hardwareInterface>
      <mechanicalReduction>1</mechanicalReduction>
    </actuator>
  </transmission>
  <transmission name="l_shoulder_base_transmission">
    <type>transmission_interface/SimpleTransmission</type>
    <joint name="l_shoulder_base_joint">
      <hardwareInterface>hardware_interface/PositionJointInterface</hardwareInterface>
    </joint>
    <actuator name="l_shoulder_base_motor">
      <hardwareInterface>hardware_interface/PositionJointInterface</hardwareInterface>
      <mechanicalReduction>1</mechanicalReduction>
    </actuator>
  </transmission>
  <transmission name="r_wrist_roll_transmission">
    <type>transmission_interface/SimpleTransmission</type>
    <joint name="r_wrist_roll_joint">
      <hardwareInterface>hardware_interface/PositionJointInterface</hardwareInterface>
    </joint>
    <actuator name="r_wrist_roll_motor">
      <hardwareInterface>hardware_interface/PositionJointInterface</hardwareInterface>
      <mechanicalReduction>1</mechanicalReduction>
    </actuator>
  </transmission>
  <transmission name="l_wrist_roll_transmission">
    <type>transmission_interface/SimpleTransmission</type>
    <joint name="l_wrist_roll_joint">
      <hardwareInterface>hardware_interface/PositionJointInterface</hardwareInterface>
    </joint>
    <actuator name="l_wrist_roll_motor">
      <hardwareInterface>hardware_interface/PositionJointInterface</hardwareInterface>
      <mechanicalReduction>1</mechanicalReduction>
    </actuator>
  </transmission>
  <gazebo>
    <plugin filename="libgazebo_ros_control.so" name="gazebo_ros_control">
      <robotNamespace>/</robotNamespace>
    </plugin>
  </gazebo>
</robot>
